# 15_错误处理

## error

> 错误和异常不同，错误是在程序中正常存在的，可以预知的失败在意料之中。而异常通常指在不应该出现问题的地方出现问题，比如空指针，这在人们的意料之外。go语言没有 try......catch 这样的方式来捕获异常所以Go定义属于自己的一种错误类型，用error表示错误。
> 通常情况一个函数如果有错误，都会在返回值最后一个，返回一个error类型的错误，根据这个值来判断是否是非nil的值，如果是nil表示没有错误，如果nil不为空，则需要进行错误处理。

::: info
error的定义是一个接口，接口内部包含一个返回字符串类型的方法Error()
:::

::: code-group

```go
type error interface {
    Error() string
}
```

:::

> 只要实现了这个接口 都可以用来处理错误信息。来返回一个错误提示给用户。Go语言也提供了一个内置包errors ，来创建一个错误对象

::: code-group

```go
package main

import (
    "errors"
    "fmt"
)

func main() {
    val, err := calculation(10, 0)
    fmt.Println(val, err)

}

func calculation(x int, y int) (int, error) {
    if y == 0 {
        // 创建错误类型，返回错误
        return 0, errors.New("错误：除数不能为零")
    }
    // 若没有错误则为nil
    return x / y, nil
}
```

:::

## panic

> 对于无法预料的错误,例如数组越界，空指针等,go语言中使用`panic`(恐慌)来表示.`panic`提供一个内置函数，供我们调用，调用后当前协程会退出,如果没有defer处理它,程序会崩溃

::: code-group

```go

package main

import "fmt"

func main() {
    panic("这是一个恐慌")
}

```

::: tip
通常建议谨慎使用 `panic`，因为它们会使错误处理变得更加复杂，并且可能导致程序的非正常终止。在大多数情况下，应该使用内置的错误返回机制来处理错误，而不是使用 `panic`。
:::

### recover 恢复恐慌

> 如果你需要在程序中处理 `panic`，可以使用 `defer` 函数和 `recover` 来恢复程序的执行

::: code-group

```go
func main() {
    myFunction()
    fmt.Println("Program continues...")
}

func myFunction() {
    defer func() {
        err := recover()
        if err != nil {
            fmt.Println("Error:", err)
        }
    }()
    panic("Something bad happened!")
    fmt.Println("Hello, World!") // 这一行不会执行
}

:::
